<sdf version='1.7'>
  <model name='vehicle'>
    <link name='base_link'>
      <inertial>
        <pose>0 0 0 0 -0 0</pose>
        <mass>10</mass>
        <inertia>
          <ixx>1</ixx>
          <ixy>0</ixy>
          <ixz>0</ixz>
          <iyy>1</iyy>
          <iyz>0</iyz>
          <izz>1</izz>
        </inertia>
      </inertial>
      <collision name='base_link_collision'>
        <pose>0 0 0 0 -0 0</pose>
        <geometry>
          <mesh>
            <scale>1 1 1</scale>
            <uri>model://vehicle/meshes/base_link.STL</uri>
          </mesh>
        </geometry>
      </collision>
      <visual name='base_link_visual'>
        <pose>0 0 0 0 -0 0</pose>
        <geometry>
          <mesh>
            <scale>1 1 1</scale>
            <uri>model://vehicle/meshes/base_link.STL</uri>
          </mesh>
        </geometry>
      </visual>
    </link>
    <joint name='JTBKL' type='revolute'>
      <pose relative_to='base_link'>-0.8 0.3 0 0 -0 0</pose>
      <parent>base_link</parent>
      <child>BKL</child>
      <axis>
        <xyz>0 1 0</xyz>
        <limit>
          <lower>-1e+16</lower>
          <upper>1e+16</upper>
        </limit>
        <dynamics>
          <spring_reference>0</spring_reference>
          <spring_stiffness>0</spring_stiffness>
        </dynamics>
      </axis>
    </joint>
    <link name='BKL'>
      <pose relative_to='JTBKL'>0 0 0 0 -0 0</pose>
      <inertial>
        <pose>0 0 0 0 -0 0</pose>
        <mass>6</mass>
        <inertia>
          <ixx>0.6</ixx>
          <ixy>0</ixy>
          <ixz>0</ixz>
          <iyy>0.6</iyy>
          <iyz>0</iyz>
          <izz>0.6</izz>
        </inertia>
      </inertial>
      <collision name='BKL_collision'>
        <pose>0 0 0 0 -0 0</pose>
        <geometry>
          <mesh>
            <scale>1 1 1</scale>
            <uri>model://vehicle/meshes/BKL.STL</uri>
          </mesh>
        </geometry>
      </collision>
      <visual name='BKL_visual'>
        <pose>0 0 0 0 -0 0</pose>
        <geometry>
          <mesh>
            <scale>1 1 1</scale>
            <uri>model://vehicle/meshes/BKL.STL</uri>
          </mesh>
        </geometry>
      </visual>
    </link>
    <joint name='JTBKR' type='revolute'>
      <pose relative_to='base_link'>-0.8 -0.3 0 0 -0 0</pose>
      <parent>base_link</parent>
      <child>BKR</child>
      <axis>
        <xyz>0 1 0</xyz>
        <limit>
          <lower>-1e+16</lower>
          <upper>1e+16</upper>
        </limit>
        <dynamics>
          <spring_reference>0</spring_reference>
          <spring_stiffness>0</spring_stiffness>
        </dynamics>
      </axis>
    </joint>
    <link name='BKR'>
      <pose relative_to='JTBKR'>0 0 0 0 -0 0</pose>
      <inertial>
        <pose>0 0 0 0 -0 0</pose>
        <mass>6</mass>
        <inertia>
          <ixx>0.6</ixx>
          <ixy>0</ixy>
          <ixz>0</ixz>
          <iyy>0.6</iyy>
          <iyz>0</iyz>
          <izz>0.6</izz>
        </inertia>
      </inertial>
      <collision name='BKR_collision'>
        <pose>0 0 0 0 -0 0</pose>
        <geometry>
          <mesh>
            <scale>1 1 1</scale>
            <uri>model://vehicle/meshes/BKR.STL</uri>
          </mesh>
        </geometry>
      </collision>
      <visual name='BKR_visual'>
        <pose>0 0 0 0 -0 0</pose>
        <geometry>
          <mesh>
            <scale>1 1 1</scale>
            <uri>model://vehicle/meshes/BKR.STL</uri>
          </mesh>
        </geometry>
      </visual>
    </link>
    <joint name='JTFRL' type='revolute'>
      <pose relative_to='base_link'>0.8 0.3 0 0 -0 0</pose>
      <parent>base_link</parent>
      <child>FRL</child>
      <axis>
        <xyz>0 1 0</xyz>
        <limit>
          <lower>0</lower>
          <upper>0</upper>
          <effort>10</effort>
          <velocity>10</velocity>
        </limit>
        <dynamics>
          <spring_reference>0</spring_reference>
          <spring_stiffness>0</spring_stiffness>
        </dynamics>
      </axis>
    </joint>
    <link name='FRL'>
      <pose relative_to='JTFRL'>0 0 0 0 -0 0</pose>
      <inertial>
        <pose>0 0 0 0 -0 0</pose>
        <mass>5</mass>
        <inertia>
          <ixx>0.5</ixx>
          <ixy>0</ixy>
          <ixz>0</ixz>
          <iyy>0.5</iyy>
          <iyz>0</iyz>
          <izz>0.5</izz>
        </inertia>
      </inertial>
      <collision name='FRL_collision'>
        <pose>0 0 0 0 -0 0</pose>
        <geometry>
          <mesh>
            <scale>1 1 1</scale>
            <uri>model://vehicle/meshes/FRL.STL</uri>
          </mesh>
        </geometry>
      </collision>
      <visual name='FRL_visual'>
        <pose>0 0 0 0 -0 0</pose>
        <geometry>
          <mesh>
            <scale>1 1 1</scale>
            <uri>model://vehicle/meshes/FRL.STL</uri>
          </mesh>
        </geometry>
      </visual>
    </link>
    <joint name='JTFRR' type='revolute'>
      <pose relative_to='base_link'>0.8 -0.3 0 0 -0 0</pose>
      <parent>base_link</parent>
      <child>FRR</child>
      <axis>
        <xyz>0 1 0</xyz>
        <limit>
          <lower>0</lower>
          <upper>0</upper>
          <effort>10</effort>
          <velocity>10</velocity>
        </limit>
        <dynamics>
          <spring_reference>0</spring_reference>
          <spring_stiffness>0</spring_stiffness>
        </dynamics>
      </axis>
    </joint>
    <link name='FRR'>
      <pose relative_to='JTFRR'>0 0 0 0 -0 0</pose>
      <inertial>
        <pose>0 0 0 0 -0 0</pose>
        <mass>5</mass>
        <inertia>
          <ixx>0.5</ixx>
          <ixy>0</ixy>
          <ixz>0</ixz>
          <iyy>0.5</iyy>
          <iyz>0</iyz>
          <izz>0.5</izz>
        </inertia>
      </inertial>
      <collision name='FRR_collision'>
        <pose>0 0 0 0 -0 0</pose>
        <geometry>
          <mesh>
            <scale>1 1 1</scale>
            <uri>model://vehicle/meshes/FRR.STL</uri>
          </mesh>
        </geometry>
      </collision>
      <visual name='FRR_visual'>
        <pose>0 0 0 0 -0 0</pose>
        <geometry>
          <mesh>
            <scale>1 1 1</scale>
            <uri>model://vehicle/meshes/FRR.STL</uri>
          </mesh>
        </geometry>
      </visual>
    </link>
  </model>
</sdf>
