<?xml version="1.0"?>
<robot name="vehicle">

  <!-- Base Link -->
  <link name="base_link">
    <inertial>
      <origin xyz="0 0 0" rpy="0 0 0" />
      <mass value="10.0" />
      <inertia ixx="1.0" ixy="0.0" ixz="0.0" iyy="1.0" iyz="0.0" izz="1.0" />
    </inertial>
    <visual>
      <origin xyz="0 0 0" rpy="0 0 0" />
      <geometry>
        <mesh filename="package://vehicle/meshes/base_link.STL" />
      </geometry>
      <material name="blue">
        <color rgba="0.0 0.0 1.0 1" />
      </material>
    </visual>
    <collision>
      <origin xyz="0 0 0" rpy="0 0 0" />
      <geometry>
        <mesh filename="package://vehicle/meshes/base_link.STL" />
      </geometry>
    </collision>
  </link>

  <!-- Front Right Wheel -->
  <link name="FRR">
    <inertial>
      <origin xyz="0 0 0" rpy="0 0 0" />
      <mass value="5.0" />
      <inertia ixx="0.5" ixy="0.0" ixz="0.0" iyy="0.5" iyz="0.0" izz="0.5" />
    </inertial>
    <visual>
      <origin xyz="0 0 0" rpy="0 0 0" />
      <geometry>
        <mesh filename="package://vehicle/meshes/FRR.STL" />
      </geometry>
    </visual>
    <collision>
      <origin xyz="0 0 0" rpy="0 0 0" />
      <geometry>
        <mesh filename="package://vehicle/meshes/FRR.STL" />
      </geometry>
    </collision>
  </link>

  <!-- Joint for Front Right Wheel -->
  <joint name="JTFRR" type="revolute">
    <origin xyz="0.8 -0.3 0.0" rpy="0 0 0" />
    <parent link="base_link" />
    <child link="FRR" />
    <axis xyz="0 1 0" />
    <limit lower="0" upper="0" effort="10" velocity="10" />
  </joint>

  <!-- Front Left Wheel -->
  <link name="FRL">
    <inertial>
      <origin xyz="0 0 0" rpy="0 0 0" />
      <mass value="5.0" />
      <inertia ixx="0.5" ixy="0.0" ixz="0.0" iyy="0.5" iyz="0.0" izz="0.5" />
    </inertial>
    <visual>
      <origin xyz="0 0 0" rpy="0 0 0" />
      <geometry>
        <mesh filename="package://vehicle/meshes/FRL.STL" />
      </geometry>
    </visual>
    <collision>
      <origin xyz="0 0 0" rpy="0 0 0" />
      <geometry>
        <mesh filename="package://vehicle/meshes/FRL.STL" />
      </geometry>
    </collision>
  </link>

  <!-- Joint for Front Left Wheel -->
  <joint name="JTFRL" type="revolute">
    <origin xyz="0.8 0.3 0.0" rpy="0 0 0" />
    <parent link="base_link" />
    <child link="FRL" />
    <axis xyz="0 1 0" />
    <limit lower="0" upper="0" effort="10" velocity="10" />
  </joint>

  <!-- Rear Left Wheel -->
  <link name="BKL">
    <inertial>
      <origin xyz="0 0 0" rpy="0 0 0" />
      <mass value="6.0" />
      <inertia ixx="0.6" ixy="0.0" ixz="0.0" iyy="0.6" iyz="0.0" izz="0.6" />
    </inertial>
    <visual>
      <origin xyz="0 0 0" rpy="0 0 0" />
      <geometry>
        <mesh filename="package://vehicle/meshes/BKL.STL" />
      </geometry>
    </visual>
    <collision>
      <origin xyz="0 0 0" rpy="0 0 0" />
      <geometry>
        <mesh filename="package://vehicle/meshes/BKL.STL" />
      </geometry>
    </collision>
  </link>

  <!-- Joint for Rear Left Wheel -->
  <joint name="JTBKL" type="continuous">
    <origin xyz="-0.8 0.3 0.0" rpy="0 0 0" />
    <parent link="base_link" />
    <child link="BKL" />
    <axis xyz="0 1 0" />
  </joint>

  <!-- Rear Right Wheel -->
  <link name="BKR">
    <inertial>
      <origin xyz="0 0 0" rpy="0 0 0" />
      <mass value="6.0" />
      <inertia ixx="0.6" ixy="0.0" ixz="0.0" iyy="0.6" iyz="0.0" izz="0.6" />
    </inertial>
    <visual>
      <origin xyz="0 0 0" rpy="0 0 0" />
      <geometry>
        <mesh filename="package://vehicle/meshes/BKR.STL" />
      </geometry>
    </visual>
    <collision>
      <origin xyz="0 0 0" rpy="0 0 0" />
      <geometry>
        <mesh filename="package://vehicle/meshes/BKR.STL" />
      </geometry>
    </collision>
  </link>

  <!-- Joint for Rear Right Wheel -->
  <joint name="JTBKR" type="continuous">
    <origin xyz="-0.8 -0.3 0.0" rpy="0 0 0" />
    <parent link="base_link" />
    <child link="BKR" />
    <axis xyz="0 1 0" />
  </joint>

  <!-- Ackermann Steering Controller -->
  <transmission name="front_left_steering_transmission">
    <type>transmission_interface/SimpleTransmission</type>
    <joint name="front_left_steering_joint">
      <hardwareInterface>hardware_interface/PositionJointInterface</hardwareInterface>
    </joint>
  </transmission>

  <transmission name="front_right_steering_transmission">
    <type>transmission_interface/SimpleTransmission</type>
    <joint name="front_right_steering_joint">
      <hardwareInterface>hardware_interface/PositionJointInterface</hardwareInterface>
    </joint>
  </transmission>

  <transmission name="rear_left_wheel_transmission">
    <type>transmission_interface/SimpleTransmission</type>
    <joint name="rear_left_wheel_joint">
      <hardwareInterface>hardware_interface/VelocityJointInterface</hardwareInterface>
    </joint>
  </transmission>

  <transmission name="rear_right_wheel_transmission">
    <type>transmission_interface/SimpleTransmission</type>
    <joint name="rear_right_wheel_joint">
      <hardwareInterface>hardware_interface/VelocityJointInterface</hardwareInterface>
    </joint>
  </transmission>

</robot>

